[2025-07-19T17:30:14.837+0000] {local_task_job_runner.py:123} INFO - ::group::Pre task execution logs
[2025-07-19T17:30:14.855+0000] {taskinstance.py:2603} INFO - Dependencies all met for dep_context=non-requeueable deps ti=<TaskInstance: banking_data_quality.generate_data scheduled__2025-07-18T17:00:00+00:00 [queued]>
[2025-07-19T17:30:14.863+0000] {taskinstance.py:2603} INFO - Dependencies all met for dep_context=requeueable deps ti=<TaskInstance: banking_data_quality.generate_data scheduled__2025-07-18T17:00:00+00:00 [queued]>
[2025-07-19T17:30:14.863+0000] {taskinstance.py:2856} INFO - Starting attempt 1 of 2
[2025-07-19T17:30:14.880+0000] {taskinstance.py:2879} INFO - Executing <Task(PythonOperator): generate_data> on 2025-07-18 17:00:00+00:00
[2025-07-19T17:30:14.888+0000] {warnings.py:112} WARNING - /home/***/.local/lib/python3.12/site-packages/***/task/task_runner/standard_task_runner.py:70: DeprecationWarning: This process (pid=68) is multi-threaded, use of fork() may lead to deadlocks in the child.
  pid = os.fork()

[2025-07-19T17:30:14.890+0000] {standard_task_runner.py:72} INFO - Started process 70 to run task
[2025-07-19T17:30:14.891+0000] {standard_task_runner.py:104} INFO - Running: ['***', 'tasks', 'run', 'banking_data_quality', 'generate_data', 'scheduled__2025-07-18T17:00:00+00:00', '--job-id', '4', '--raw', '--subdir', 'DAGS_FOLDER/banking_dq_dag.py', '--cfg-path', '/tmp/tmpq1cqfb_x']
[2025-07-19T17:30:14.893+0000] {standard_task_runner.py:105} INFO - Job 4: Subtask generate_data
[2025-07-19T17:30:14.945+0000] {task_command.py:467} INFO - Running <TaskInstance: banking_data_quality.generate_data scheduled__2025-07-18T17:00:00+00:00 [running]> on host 894e965ab49e
[2025-07-19T17:30:15.031+0000] {taskinstance.py:3122} INFO - Exporting env vars: AIRFLOW_CTX_DAG_OWNER='***' AIRFLOW_CTX_DAG_ID='banking_data_quality' AIRFLOW_CTX_TASK_ID='generate_data' AIRFLOW_CTX_EXECUTION_DATE='2025-07-18T17:00:00+00:00' AIRFLOW_CTX_TRY_NUMBER='1' AIRFLOW_CTX_DAG_RUN_ID='scheduled__2025-07-18T17:00:00+00:00'
[2025-07-19T17:30:15.031+0000] {taskinstance.py:731} INFO - ::endgroup::
[2025-07-19T17:30:15.070+0000] {logging_mixin.py:190} INFO - --------connect success---------
[2025-07-19T17:32:28.437+0000] {logging_mixin.py:190} INFO - Data generation failed: 2003 (HY000): Can't connect to MySQL server on '172.17.0.2:3306' (110)
[2025-07-19T17:32:28.437+0000] {taskinstance.py:3301} ERROR - Task failed with exception
Traceback (most recent call last):
  File "/home/airflow/.local/lib/python3.12/site-packages/mysql/connector/connection_cext.py", line 334, in _open_connection
    self._cmysql.connect(**cnx_kwargs)
_mysql_connector.MySQLInterfaceError: Can't connect to MySQL server on '172.17.0.2:3306' (110)

The above exception was the direct cause of the following exception:

Traceback (most recent call last):
  File "/home/airflow/.local/lib/python3.12/site-packages/airflow/models/taskinstance.py", line 767, in _execute_task
    result = _execute_callable(context=context, **execute_callable_kwargs)
             ^^^^^^^^^^^^^^^^^^^^^^^^^^^^^^^^^^^^^^^^^^^^^^^^^^^^^^^^^^^^^
  File "/home/airflow/.local/lib/python3.12/site-packages/airflow/models/taskinstance.py", line 733, in _execute_callable
    return ExecutionCallableRunner(
           ^^^^^^^^^^^^^^^^^^^^^^^^
  File "/home/airflow/.local/lib/python3.12/site-packages/airflow/utils/operator_helpers.py", line 252, in run
    return self.func(*args, **kwargs)
           ^^^^^^^^^^^^^^^^^^^^^^^^^^
  File "/home/airflow/.local/lib/python3.12/site-packages/airflow/models/baseoperator.py", line 406, in wrapper
    return func(self, *args, **kwargs)
           ^^^^^^^^^^^^^^^^^^^^^^^^^^^
  File "/home/airflow/.local/lib/python3.12/site-packages/airflow/operators/python.py", line 238, in execute
    return_value = self.execute_callable()
                   ^^^^^^^^^^^^^^^^^^^^^^^
  File "/home/airflow/.local/lib/python3.12/site-packages/airflow/operators/python.py", line 256, in execute_callable
    return runner.run(*self.op_args, **self.op_kwargs)
           ^^^^^^^^^^^^^^^^^^^^^^^^^^^^^^^^^^^^^^^^^^^
  File "/home/airflow/.local/lib/python3.12/site-packages/airflow/utils/operator_helpers.py", line 252, in run
    return self.func(*args, **kwargs)
           ^^^^^^^^^^^^^^^^^^^^^^^^^^
  File "/opt/airflow/dags/banking_dq_dag.py", line 32, in run_generate_data
    generate_data()
  File "/opt/airflow/include/generate_data.py", line 40, in generate_data
    conn = connect_db()
           ^^^^^^^^^^^^
  File "/opt/airflow/include/generate_data.py", line 23, in connect_db
    return mysql.connector.connect(**DB_PARAMS)
           ^^^^^^^^^^^^^^^^^^^^^^^^^^^^^^^^^^^^
  File "/home/airflow/.local/lib/python3.12/site-packages/mysql/connector/pooling.py", line 322, in connect
    return CMySQLConnection(*args, **kwargs)
           ^^^^^^^^^^^^^^^^^^^^^^^^^^^^^^^^^
  File "/home/airflow/.local/lib/python3.12/site-packages/mysql/connector/connection_cext.py", line 151, in __init__
    self.connect(**kwargs)
  File "/home/airflow/.local/lib/python3.12/site-packages/mysql/connector/abstracts.py", line 1399, in connect
    self._open_connection()
  File "/home/airflow/.local/lib/python3.12/site-packages/mysql/connector/connection_cext.py", line 339, in _open_connection
    raise get_mysql_exception(
mysql.connector.errors.DatabaseError: 2003 (HY000): Can't connect to MySQL server on '172.17.0.2:3306' (110)
[2025-07-19T17:32:28.452+0000] {taskinstance.py:1225} INFO - Marking task as UP_FOR_RETRY. dag_id=banking_data_quality, task_id=generate_data, run_id=scheduled__2025-07-18T17:00:00+00:00, execution_date=20250718T170000, start_date=20250719T173014, end_date=20250719T173228
[2025-07-19T17:32:28.467+0000] {taskinstance.py:340} INFO - ::group::Post task execution logs
[2025-07-19T17:32:28.468+0000] {standard_task_runner.py:124} ERROR - Failed to execute job 4 for task generate_data (2003 (HY000): Can't connect to MySQL server on '172.17.0.2:3306' (110); 70)
Traceback (most recent call last):
  File "/home/airflow/.local/lib/python3.12/site-packages/mysql/connector/connection_cext.py", line 334, in _open_connection
    self._cmysql.connect(**cnx_kwargs)
_mysql_connector.MySQLInterfaceError: Can't connect to MySQL server on '172.17.0.2:3306' (110)

The above exception was the direct cause of the following exception:

Traceback (most recent call last):
  File "/home/airflow/.local/lib/python3.12/site-packages/airflow/task/task_runner/standard_task_runner.py", line 117, in _start_by_fork
    ret = args.func(args, dag=self.dag)
          ^^^^^^^^^^^^^^^^^^^^^^^^^^^^^
  File "/home/airflow/.local/lib/python3.12/site-packages/airflow/cli/cli_config.py", line 49, in command
    return func(*args, **kwargs)
           ^^^^^^^^^^^^^^^^^^^^^
  File "/home/airflow/.local/lib/python3.12/site-packages/airflow/utils/cli.py", line 115, in wrapper
    return f(*args, **kwargs)
           ^^^^^^^^^^^^^^^^^^
  File "/home/airflow/.local/lib/python3.12/site-packages/airflow/cli/commands/task_command.py", line 483, in task_run
    task_return_code = _run_task_by_selected_method(args, _dag, ti)
                       ^^^^^^^^^^^^^^^^^^^^^^^^^^^^^^^^^^^^^^^^^^^^
  File "/home/airflow/.local/lib/python3.12/site-packages/airflow/cli/commands/task_command.py", line 256, in _run_task_by_selected_method
    return _run_raw_task(args, ti)
           ^^^^^^^^^^^^^^^^^^^^^^^
  File "/home/airflow/.local/lib/python3.12/site-packages/airflow/cli/commands/task_command.py", line 341, in _run_raw_task
    return ti._run_raw_task(
           ^^^^^^^^^^^^^^^^^
  File "/home/airflow/.local/lib/python3.12/site-packages/airflow/utils/session.py", line 97, in wrapper
    return func(*args, session=session, **kwargs)
           ^^^^^^^^^^^^^^^^^^^^^^^^^^^^^^^^^^^^^^
  File "/home/airflow/.local/lib/python3.12/site-packages/airflow/models/taskinstance.py", line 2995, in _run_raw_task
    return _run_raw_task(
           ^^^^^^^^^^^^^^
  File "/home/airflow/.local/lib/python3.12/site-packages/airflow/models/taskinstance.py", line 273, in _run_raw_task
    TaskInstance._execute_task_with_callbacks(
  File "/home/airflow/.local/lib/python3.12/site-packages/airflow/models/taskinstance.py", line 3149, in _execute_task_with_callbacks
    result = self._execute_task(context, task_orig)
             ^^^^^^^^^^^^^^^^^^^^^^^^^^^^^^^^^^^^^^
  File "/home/airflow/.local/lib/python3.12/site-packages/airflow/models/taskinstance.py", line 3173, in _execute_task
    return _execute_task(self, context, task_orig)
           ^^^^^^^^^^^^^^^^^^^^^^^^^^^^^^^^^^^^^^^
  File "/home/airflow/.local/lib/python3.12/site-packages/airflow/models/taskinstance.py", line 767, in _execute_task
    result = _execute_callable(context=context, **execute_callable_kwargs)
             ^^^^^^^^^^^^^^^^^^^^^^^^^^^^^^^^^^^^^^^^^^^^^^^^^^^^^^^^^^^^^
  File "/home/airflow/.local/lib/python3.12/site-packages/airflow/models/taskinstance.py", line 733, in _execute_callable
    return ExecutionCallableRunner(
           ^^^^^^^^^^^^^^^^^^^^^^^^
  File "/home/airflow/.local/lib/python3.12/site-packages/airflow/utils/operator_helpers.py", line 252, in run
    return self.func(*args, **kwargs)
           ^^^^^^^^^^^^^^^^^^^^^^^^^^
  File "/home/airflow/.local/lib/python3.12/site-packages/airflow/models/baseoperator.py", line 406, in wrapper
    return func(self, *args, **kwargs)
           ^^^^^^^^^^^^^^^^^^^^^^^^^^^
  File "/home/airflow/.local/lib/python3.12/site-packages/airflow/operators/python.py", line 238, in execute
    return_value = self.execute_callable()
                   ^^^^^^^^^^^^^^^^^^^^^^^
  File "/home/airflow/.local/lib/python3.12/site-packages/airflow/operators/python.py", line 256, in execute_callable
    return runner.run(*self.op_args, **self.op_kwargs)
           ^^^^^^^^^^^^^^^^^^^^^^^^^^^^^^^^^^^^^^^^^^^
  File "/home/airflow/.local/lib/python3.12/site-packages/airflow/utils/operator_helpers.py", line 252, in run
    return self.func(*args, **kwargs)
           ^^^^^^^^^^^^^^^^^^^^^^^^^^
  File "/opt/airflow/dags/banking_dq_dag.py", line 32, in run_generate_data
    generate_data()
  File "/opt/airflow/include/generate_data.py", line 40, in generate_data
    conn = connect_db()
           ^^^^^^^^^^^^
  File "/opt/airflow/include/generate_data.py", line 23, in connect_db
    return mysql.connector.connect(**DB_PARAMS)
           ^^^^^^^^^^^^^^^^^^^^^^^^^^^^^^^^^^^^
  File "/home/airflow/.local/lib/python3.12/site-packages/mysql/connector/pooling.py", line 322, in connect
    return CMySQLConnection(*args, **kwargs)
           ^^^^^^^^^^^^^^^^^^^^^^^^^^^^^^^^^
  File "/home/airflow/.local/lib/python3.12/site-packages/mysql/connector/connection_cext.py", line 151, in __init__
    self.connect(**kwargs)
  File "/home/airflow/.local/lib/python3.12/site-packages/mysql/connector/abstracts.py", line 1399, in connect
    self._open_connection()
  File "/home/airflow/.local/lib/python3.12/site-packages/mysql/connector/connection_cext.py", line 339, in _open_connection
    raise get_mysql_exception(
mysql.connector.errors.DatabaseError: 2003 (HY000): Can't connect to MySQL server on '172.17.0.2:3306' (110)
[2025-07-19T17:32:28.504+0000] {local_task_job_runner.py:261} INFO - Task exited with return code 1
[2025-07-19T17:32:28.525+0000] {taskinstance.py:3891} INFO - 0 downstream tasks scheduled from follow-on schedule check
[2025-07-19T17:32:28.527+0000] {local_task_job_runner.py:240} INFO - ::endgroup::
[2025-07-19T17:59:16.139+0000] {local_task_job_runner.py:123} INFO - ::group::Pre task execution logs
[2025-07-19T17:59:16.159+0000] {taskinstance.py:2603} INFO - Dependencies all met for dep_context=non-requeueable deps ti=<TaskInstance: banking_data_quality.generate_data scheduled__2025-07-18T17:00:00+00:00 [queued]>
[2025-07-19T17:59:16.166+0000] {taskinstance.py:2603} INFO - Dependencies all met for dep_context=requeueable deps ti=<TaskInstance: banking_data_quality.generate_data scheduled__2025-07-18T17:00:00+00:00 [queued]>
[2025-07-19T17:59:16.167+0000] {taskinstance.py:2856} INFO - Starting attempt 1 of 2
[2025-07-19T17:59:16.188+0000] {taskinstance.py:2879} INFO - Executing <Task(PythonOperator): generate_data> on 2025-07-18 17:00:00+00:00
[2025-07-19T17:59:16.197+0000] {warnings.py:112} WARNING - /home/***/.local/lib/python3.12/site-packages/***/task/task_runner/standard_task_runner.py:70: DeprecationWarning: This process (pid=68) is multi-threaded, use of fork() may lead to deadlocks in the child.
  pid = os.fork()

[2025-07-19T17:59:16.198+0000] {standard_task_runner.py:72} INFO - Started process 70 to run task
[2025-07-19T17:59:16.199+0000] {standard_task_runner.py:104} INFO - Running: ['***', 'tasks', 'run', 'banking_data_quality', 'generate_data', 'scheduled__2025-07-18T17:00:00+00:00', '--job-id', '4', '--raw', '--subdir', 'DAGS_FOLDER/banking_dq_dag.py', '--cfg-path', '/tmp/tmp7dbxc5fy']
[2025-07-19T17:59:16.201+0000] {standard_task_runner.py:105} INFO - Job 4: Subtask generate_data
[2025-07-19T17:59:16.251+0000] {task_command.py:467} INFO - Running <TaskInstance: banking_data_quality.generate_data scheduled__2025-07-18T17:00:00+00:00 [running]> on host 2e145ce6e7b6
[2025-07-19T17:59:16.339+0000] {taskinstance.py:3122} INFO - Exporting env vars: AIRFLOW_CTX_DAG_OWNER='***' AIRFLOW_CTX_DAG_ID='banking_data_quality' AIRFLOW_CTX_TASK_ID='generate_data' AIRFLOW_CTX_EXECUTION_DATE='2025-07-18T17:00:00+00:00' AIRFLOW_CTX_TRY_NUMBER='1' AIRFLOW_CTX_DAG_RUN_ID='scheduled__2025-07-18T17:00:00+00:00'
[2025-07-19T17:59:16.341+0000] {taskinstance.py:731} INFO - ::endgroup::
[2025-07-19T17:59:16.383+0000] {logging_mixin.py:190} INFO - --------connect success---------
[2025-07-19T18:00:36.910+0000] {local_task_job_runner.py:341} WARNING - State of this instance has been externally set to queued. Terminating instance.
[2025-07-19T18:00:36.912+0000] {local_task_job_runner.py:240} INFO - ::endgroup::
[2025-07-19T18:00:36.914+0000] {process_utils.py:132} INFO - Sending 15 to group 70. PIDs of all processes in the group: [70]
[2025-07-19T18:00:36.914+0000] {process_utils.py:87} INFO - Sending the signal 15 to group 70
[2025-07-19T18:01:29.237+0000] {taskinstance.py:3083} ERROR - Received SIGTERM. Terminating subprocesses.
[2025-07-19T18:01:29.252+0000] {taskinstance.py:3301} ERROR - Task failed with exception
Traceback (most recent call last):
  File "/home/airflow/.local/lib/python3.12/site-packages/mysql/connector/connection_cext.py", line 334, in _open_connection
    self._cmysql.connect(**cnx_kwargs)
_mysql_connector.MySQLInterfaceError: Can't connect to MySQL server on '172.17.0.2:3306' (110)

During handling of the above exception, another exception occurred:

Traceback (most recent call last):
  File "/home/airflow/.local/lib/python3.12/site-packages/airflow/models/taskinstance.py", line 767, in _execute_task
    result = _execute_callable(context=context, **execute_callable_kwargs)
             ^^^^^^^^^^^^^^^^^^^^^^^^^^^^^^^^^^^^^^^^^^^^^^^^^^^^^^^^^^^^^
  File "/home/airflow/.local/lib/python3.12/site-packages/airflow/models/taskinstance.py", line 733, in _execute_callable
    return ExecutionCallableRunner(
           ^^^^^^^^^^^^^^^^^^^^^^^^
  File "/home/airflow/.local/lib/python3.12/site-packages/airflow/utils/operator_helpers.py", line 252, in run
    return self.func(*args, **kwargs)
           ^^^^^^^^^^^^^^^^^^^^^^^^^^
  File "/home/airflow/.local/lib/python3.12/site-packages/airflow/models/baseoperator.py", line 406, in wrapper
    return func(self, *args, **kwargs)
           ^^^^^^^^^^^^^^^^^^^^^^^^^^^
  File "/home/airflow/.local/lib/python3.12/site-packages/airflow/operators/python.py", line 238, in execute
    return_value = self.execute_callable()
                   ^^^^^^^^^^^^^^^^^^^^^^^
  File "/home/airflow/.local/lib/python3.12/site-packages/airflow/operators/python.py", line 256, in execute_callable
    return runner.run(*self.op_args, **self.op_kwargs)
           ^^^^^^^^^^^^^^^^^^^^^^^^^^^^^^^^^^^^^^^^^^^
  File "/home/airflow/.local/lib/python3.12/site-packages/airflow/utils/operator_helpers.py", line 252, in run
    return self.func(*args, **kwargs)
           ^^^^^^^^^^^^^^^^^^^^^^^^^^
  File "/opt/airflow/dags/banking_dq_dag.py", line 32, in run_generate_data
    generate_data()
  File "/opt/airflow/include/generate_data.py", line 40, in generate_data
    conn = connect_db()
           ^^^^^^^^^^^^
  File "/opt/airflow/include/generate_data.py", line 23, in connect_db
    return mysql.connector.connect(**DB_PARAMS)
           ^^^^^^^^^^^^^^^^^^^^^^^^^^^^^^^^^^^^
  File "/home/airflow/.local/lib/python3.12/site-packages/mysql/connector/pooling.py", line 322, in connect
    return CMySQLConnection(*args, **kwargs)
           ^^^^^^^^^^^^^^^^^^^^^^^^^^^^^^^^^
  File "/home/airflow/.local/lib/python3.12/site-packages/mysql/connector/connection_cext.py", line 151, in __init__
    self.connect(**kwargs)
  File "/home/airflow/.local/lib/python3.12/site-packages/mysql/connector/abstracts.py", line 1399, in connect
    self._open_connection()
  File "/home/airflow/.local/lib/python3.12/site-packages/mysql/connector/connection_cext.py", line 339, in _open_connection
    raise get_mysql_exception(
          ^^^^^^^^^^^^^^^^^^^^
  File "/home/airflow/.local/lib/python3.12/site-packages/mysql/connector/errors.py", line 222, in get_mysql_exception
    def get_mysql_exception(
    
  File "/home/airflow/.local/lib/python3.12/site-packages/airflow/models/taskinstance.py", line 3085, in signal_handler
    raise AirflowTaskTerminated("Task received SIGTERM signal")
airflow.exceptions.AirflowTaskTerminated: Task received SIGTERM signal
[2025-07-19T18:01:29.260+0000] {taskinstance.py:1225} INFO - Marking task as UP_FOR_RETRY. dag_id=banking_data_quality, task_id=generate_data, run_id=scheduled__2025-07-18T17:00:00+00:00, execution_date=20250718T170000, start_date=20250719T180037, end_date=20250719T180129
[2025-07-19T18:01:29.276+0000] {taskinstance.py:340} INFO - ::group::Post task execution logs
[2025-07-19T18:01:29.316+0000] {process_utils.py:80} INFO - Process psutil.Process(pid=70, status='terminated', exitcode=2, started='17:59:15') (70) terminated with exit code 2
[2025-07-19T18:13:54.905+0000] {local_task_job_runner.py:123} INFO - ::group::Pre task execution logs
[2025-07-19T18:13:54.930+0000] {taskinstance.py:2603} INFO - Dependencies all met for dep_context=non-requeueable deps ti=<TaskInstance: banking_data_quality.generate_data scheduled__2025-07-18T17:00:00+00:00 [queued]>
[2025-07-19T18:13:54.939+0000] {taskinstance.py:2603} INFO - Dependencies all met for dep_context=requeueable deps ti=<TaskInstance: banking_data_quality.generate_data scheduled__2025-07-18T17:00:00+00:00 [queued]>
[2025-07-19T18:13:54.940+0000] {taskinstance.py:2856} INFO - Starting attempt 1 of 2
[2025-07-19T18:13:54.957+0000] {taskinstance.py:2879} INFO - Executing <Task(PythonOperator): generate_data> on 2025-07-18 17:00:00+00:00
[2025-07-19T18:13:54.966+0000] {warnings.py:112} WARNING - /home/***/.local/lib/python3.12/site-packages/***/task/task_runner/standard_task_runner.py:70: DeprecationWarning: This process (pid=68) is multi-threaded, use of fork() may lead to deadlocks in the child.
  pid = os.fork()

[2025-07-19T18:13:54.967+0000] {standard_task_runner.py:72} INFO - Started process 70 to run task
[2025-07-19T18:13:54.968+0000] {standard_task_runner.py:104} INFO - Running: ['***', 'tasks', 'run', 'banking_data_quality', 'generate_data', 'scheduled__2025-07-18T17:00:00+00:00', '--job-id', '4', '--raw', '--subdir', 'DAGS_FOLDER/banking_dq_dag.py', '--cfg-path', '/tmp/tmpu4n3a07o']
[2025-07-19T18:13:54.972+0000] {standard_task_runner.py:105} INFO - Job 4: Subtask generate_data
[2025-07-19T18:13:55.030+0000] {task_command.py:467} INFO - Running <TaskInstance: banking_data_quality.generate_data scheduled__2025-07-18T17:00:00+00:00 [running]> on host 357ca0968dee
[2025-07-19T18:13:55.118+0000] {taskinstance.py:3122} INFO - Exporting env vars: AIRFLOW_CTX_DAG_OWNER='***' AIRFLOW_CTX_DAG_ID='banking_data_quality' AIRFLOW_CTX_TASK_ID='generate_data' AIRFLOW_CTX_EXECUTION_DATE='2025-07-18T17:00:00+00:00' AIRFLOW_CTX_TRY_NUMBER='1' AIRFLOW_CTX_DAG_RUN_ID='scheduled__2025-07-18T17:00:00+00:00'
[2025-07-19T18:13:55.119+0000] {taskinstance.py:731} INFO - ::endgroup::
[2025-07-19T18:13:55.153+0000] {logging_mixin.py:190} INFO - --------connect success---------
[2025-07-19T18:13:55.154+0000] {logging_mixin.py:190} INFO - Data generation failed: 2003 (HY000): Can't connect to MySQL server on '172.19.0.2:3306' (111)
[2025-07-19T18:13:55.155+0000] {taskinstance.py:3301} ERROR - Task failed with exception
Traceback (most recent call last):
  File "/home/airflow/.local/lib/python3.12/site-packages/mysql/connector/connection_cext.py", line 334, in _open_connection
    self._cmysql.connect(**cnx_kwargs)
_mysql_connector.MySQLInterfaceError: Can't connect to MySQL server on '172.19.0.2:3306' (111)

The above exception was the direct cause of the following exception:

Traceback (most recent call last):
  File "/home/airflow/.local/lib/python3.12/site-packages/airflow/models/taskinstance.py", line 767, in _execute_task
    result = _execute_callable(context=context, **execute_callable_kwargs)
             ^^^^^^^^^^^^^^^^^^^^^^^^^^^^^^^^^^^^^^^^^^^^^^^^^^^^^^^^^^^^^
  File "/home/airflow/.local/lib/python3.12/site-packages/airflow/models/taskinstance.py", line 733, in _execute_callable
    return ExecutionCallableRunner(
           ^^^^^^^^^^^^^^^^^^^^^^^^
  File "/home/airflow/.local/lib/python3.12/site-packages/airflow/utils/operator_helpers.py", line 252, in run
    return self.func(*args, **kwargs)
           ^^^^^^^^^^^^^^^^^^^^^^^^^^
  File "/home/airflow/.local/lib/python3.12/site-packages/airflow/models/baseoperator.py", line 406, in wrapper
    return func(self, *args, **kwargs)
           ^^^^^^^^^^^^^^^^^^^^^^^^^^^
  File "/home/airflow/.local/lib/python3.12/site-packages/airflow/operators/python.py", line 238, in execute
    return_value = self.execute_callable()
                   ^^^^^^^^^^^^^^^^^^^^^^^
  File "/home/airflow/.local/lib/python3.12/site-packages/airflow/operators/python.py", line 256, in execute_callable
    return runner.run(*self.op_args, **self.op_kwargs)
           ^^^^^^^^^^^^^^^^^^^^^^^^^^^^^^^^^^^^^^^^^^^
  File "/home/airflow/.local/lib/python3.12/site-packages/airflow/utils/operator_helpers.py", line 252, in run
    return self.func(*args, **kwargs)
           ^^^^^^^^^^^^^^^^^^^^^^^^^^
  File "/opt/airflow/dags/banking_dq_dag.py", line 32, in run_generate_data
    generate_data()
  File "/opt/airflow/include/generate_data.py", line 40, in generate_data
    conn = connect_db()
           ^^^^^^^^^^^^
  File "/opt/airflow/include/generate_data.py", line 23, in connect_db
    return mysql.connector.connect(**DB_PARAMS)
           ^^^^^^^^^^^^^^^^^^^^^^^^^^^^^^^^^^^^
  File "/home/airflow/.local/lib/python3.12/site-packages/mysql/connector/pooling.py", line 322, in connect
    return CMySQLConnection(*args, **kwargs)
           ^^^^^^^^^^^^^^^^^^^^^^^^^^^^^^^^^
  File "/home/airflow/.local/lib/python3.12/site-packages/mysql/connector/connection_cext.py", line 151, in __init__
    self.connect(**kwargs)
  File "/home/airflow/.local/lib/python3.12/site-packages/mysql/connector/abstracts.py", line 1399, in connect
    self._open_connection()
  File "/home/airflow/.local/lib/python3.12/site-packages/mysql/connector/connection_cext.py", line 339, in _open_connection
    raise get_mysql_exception(
mysql.connector.errors.DatabaseError: 2003 (HY000): Can't connect to MySQL server on '172.19.0.2:3306' (111)
[2025-07-19T18:13:55.172+0000] {taskinstance.py:1225} INFO - Marking task as UP_FOR_RETRY. dag_id=banking_data_quality, task_id=generate_data, run_id=scheduled__2025-07-18T17:00:00+00:00, execution_date=20250718T170000, start_date=20250719T181354, end_date=20250719T181355
[2025-07-19T18:13:55.191+0000] {taskinstance.py:340} INFO - ::group::Post task execution logs
[2025-07-19T18:13:55.192+0000] {standard_task_runner.py:124} ERROR - Failed to execute job 4 for task generate_data (2003 (HY000): Can't connect to MySQL server on '172.19.0.2:3306' (111); 70)
Traceback (most recent call last):
  File "/home/airflow/.local/lib/python3.12/site-packages/mysql/connector/connection_cext.py", line 334, in _open_connection
    self._cmysql.connect(**cnx_kwargs)
_mysql_connector.MySQLInterfaceError: Can't connect to MySQL server on '172.19.0.2:3306' (111)

The above exception was the direct cause of the following exception:

Traceback (most recent call last):
  File "/home/airflow/.local/lib/python3.12/site-packages/airflow/task/task_runner/standard_task_runner.py", line 117, in _start_by_fork
    ret = args.func(args, dag=self.dag)
          ^^^^^^^^^^^^^^^^^^^^^^^^^^^^^
  File "/home/airflow/.local/lib/python3.12/site-packages/airflow/cli/cli_config.py", line 49, in command
    return func(*args, **kwargs)
           ^^^^^^^^^^^^^^^^^^^^^
  File "/home/airflow/.local/lib/python3.12/site-packages/airflow/utils/cli.py", line 115, in wrapper
    return f(*args, **kwargs)
           ^^^^^^^^^^^^^^^^^^
  File "/home/airflow/.local/lib/python3.12/site-packages/airflow/cli/commands/task_command.py", line 483, in task_run
    task_return_code = _run_task_by_selected_method(args, _dag, ti)
                       ^^^^^^^^^^^^^^^^^^^^^^^^^^^^^^^^^^^^^^^^^^^^
  File "/home/airflow/.local/lib/python3.12/site-packages/airflow/cli/commands/task_command.py", line 256, in _run_task_by_selected_method
    return _run_raw_task(args, ti)
           ^^^^^^^^^^^^^^^^^^^^^^^
  File "/home/airflow/.local/lib/python3.12/site-packages/airflow/cli/commands/task_command.py", line 341, in _run_raw_task
    return ti._run_raw_task(
           ^^^^^^^^^^^^^^^^^
  File "/home/airflow/.local/lib/python3.12/site-packages/airflow/utils/session.py", line 97, in wrapper
    return func(*args, session=session, **kwargs)
           ^^^^^^^^^^^^^^^^^^^^^^^^^^^^^^^^^^^^^^
  File "/home/airflow/.local/lib/python3.12/site-packages/airflow/models/taskinstance.py", line 2995, in _run_raw_task
    return _run_raw_task(
           ^^^^^^^^^^^^^^
  File "/home/airflow/.local/lib/python3.12/site-packages/airflow/models/taskinstance.py", line 273, in _run_raw_task
    TaskInstance._execute_task_with_callbacks(
  File "/home/airflow/.local/lib/python3.12/site-packages/airflow/models/taskinstance.py", line 3149, in _execute_task_with_callbacks
    result = self._execute_task(context, task_orig)
             ^^^^^^^^^^^^^^^^^^^^^^^^^^^^^^^^^^^^^^
  File "/home/airflow/.local/lib/python3.12/site-packages/airflow/models/taskinstance.py", line 3173, in _execute_task
    return _execute_task(self, context, task_orig)
           ^^^^^^^^^^^^^^^^^^^^^^^^^^^^^^^^^^^^^^^
  File "/home/airflow/.local/lib/python3.12/site-packages/airflow/models/taskinstance.py", line 767, in _execute_task
    result = _execute_callable(context=context, **execute_callable_kwargs)
             ^^^^^^^^^^^^^^^^^^^^^^^^^^^^^^^^^^^^^^^^^^^^^^^^^^^^^^^^^^^^^
  File "/home/airflow/.local/lib/python3.12/site-packages/airflow/models/taskinstance.py", line 733, in _execute_callable
    return ExecutionCallableRunner(
           ^^^^^^^^^^^^^^^^^^^^^^^^
  File "/home/airflow/.local/lib/python3.12/site-packages/airflow/utils/operator_helpers.py", line 252, in run
    return self.func(*args, **kwargs)
           ^^^^^^^^^^^^^^^^^^^^^^^^^^
  File "/home/airflow/.local/lib/python3.12/site-packages/airflow/models/baseoperator.py", line 406, in wrapper
    return func(self, *args, **kwargs)
           ^^^^^^^^^^^^^^^^^^^^^^^^^^^
  File "/home/airflow/.local/lib/python3.12/site-packages/airflow/operators/python.py", line 238, in execute
    return_value = self.execute_callable()
                   ^^^^^^^^^^^^^^^^^^^^^^^
  File "/home/airflow/.local/lib/python3.12/site-packages/airflow/operators/python.py", line 256, in execute_callable
    return runner.run(*self.op_args, **self.op_kwargs)
           ^^^^^^^^^^^^^^^^^^^^^^^^^^^^^^^^^^^^^^^^^^^
  File "/home/airflow/.local/lib/python3.12/site-packages/airflow/utils/operator_helpers.py", line 252, in run
    return self.func(*args, **kwargs)
           ^^^^^^^^^^^^^^^^^^^^^^^^^^
  File "/opt/airflow/dags/banking_dq_dag.py", line 32, in run_generate_data
    generate_data()
  File "/opt/airflow/include/generate_data.py", line 40, in generate_data
    conn = connect_db()
           ^^^^^^^^^^^^
  File "/opt/airflow/include/generate_data.py", line 23, in connect_db
    return mysql.connector.connect(**DB_PARAMS)
           ^^^^^^^^^^^^^^^^^^^^^^^^^^^^^^^^^^^^
  File "/home/airflow/.local/lib/python3.12/site-packages/mysql/connector/pooling.py", line 322, in connect
    return CMySQLConnection(*args, **kwargs)
           ^^^^^^^^^^^^^^^^^^^^^^^^^^^^^^^^^
  File "/home/airflow/.local/lib/python3.12/site-packages/mysql/connector/connection_cext.py", line 151, in __init__
    self.connect(**kwargs)
  File "/home/airflow/.local/lib/python3.12/site-packages/mysql/connector/abstracts.py", line 1399, in connect
    self._open_connection()
  File "/home/airflow/.local/lib/python3.12/site-packages/mysql/connector/connection_cext.py", line 339, in _open_connection
    raise get_mysql_exception(
mysql.connector.errors.DatabaseError: 2003 (HY000): Can't connect to MySQL server on '172.19.0.2:3306' (111)
[2025-07-19T18:13:55.222+0000] {local_task_job_runner.py:261} INFO - Task exited with return code 1
[2025-07-19T18:13:55.247+0000] {taskinstance.py:3891} INFO - 0 downstream tasks scheduled from follow-on schedule check
[2025-07-19T18:13:55.249+0000] {local_task_job_runner.py:240} INFO - ::endgroup::
