[2025-07-19T17:37:29.934+0000] {local_task_job_runner.py:123} INFO - ::group::Pre task execution logs
[2025-07-19T17:37:29.950+0000] {taskinstance.py:2603} INFO - Dependencies all met for dep_context=non-requeueable deps ti=<TaskInstance: banking_data_quality.generate_data scheduled__2025-07-18T17:00:00+00:00 [queued]>
[2025-07-19T17:37:29.959+0000] {taskinstance.py:2603} INFO - Dependencies all met for dep_context=requeueable deps ti=<TaskInstance: banking_data_quality.generate_data scheduled__2025-07-18T17:00:00+00:00 [queued]>
[2025-07-19T17:37:29.959+0000] {taskinstance.py:2856} INFO - Starting attempt 2 of 2
[2025-07-19T17:37:29.971+0000] {taskinstance.py:2879} INFO - Executing <Task(PythonOperator): generate_data> on 2025-07-18 17:00:00+00:00
[2025-07-19T17:37:29.978+0000] {warnings.py:112} WARNING - /home/***/.local/lib/python3.12/site-packages/***/task/task_runner/standard_task_runner.py:70: DeprecationWarning: This process (pid=169) is multi-threaded, use of fork() may lead to deadlocks in the child.
  pid = os.fork()

[2025-07-19T17:37:29.979+0000] {standard_task_runner.py:72} INFO - Started process 171 to run task
[2025-07-19T17:37:29.980+0000] {standard_task_runner.py:104} INFO - Running: ['***', 'tasks', 'run', 'banking_data_quality', 'generate_data', 'scheduled__2025-07-18T17:00:00+00:00', '--job-id', '6', '--raw', '--subdir', 'DAGS_FOLDER/banking_dq_dag.py', '--cfg-path', '/tmp/tmp1w4bqqay']
[2025-07-19T17:37:29.982+0000] {standard_task_runner.py:105} INFO - Job 6: Subtask generate_data
[2025-07-19T17:37:30.026+0000] {task_command.py:467} INFO - Running <TaskInstance: banking_data_quality.generate_data scheduled__2025-07-18T17:00:00+00:00 [running]> on host 894e965ab49e
[2025-07-19T17:37:30.096+0000] {taskinstance.py:3122} INFO - Exporting env vars: AIRFLOW_CTX_DAG_OWNER='***' AIRFLOW_CTX_DAG_ID='banking_data_quality' AIRFLOW_CTX_TASK_ID='generate_data' AIRFLOW_CTX_EXECUTION_DATE='2025-07-18T17:00:00+00:00' AIRFLOW_CTX_TRY_NUMBER='2' AIRFLOW_CTX_DAG_RUN_ID='scheduled__2025-07-18T17:00:00+00:00'
[2025-07-19T17:37:30.097+0000] {taskinstance.py:731} INFO - ::endgroup::
[2025-07-19T17:37:30.112+0000] {logging_mixin.py:190} INFO - --------connect success---------
[2025-07-19T17:38:15.408+0000] {local_task_job_runner.py:341} WARNING - State of this instance has been externally set to restarting. Terminating instance.
[2025-07-19T17:38:15.409+0000] {local_task_job_runner.py:240} INFO - ::endgroup::
[2025-07-19T17:38:15.411+0000] {process_utils.py:132} INFO - Sending 15 to group 171. PIDs of all processes in the group: [171]
[2025-07-19T17:38:15.411+0000] {process_utils.py:87} INFO - Sending the signal 15 to group 171
[2025-07-19T17:39:15.449+0000] {process_utils.py:150} WARNING - process psutil.Process(pid=171, name='airflow task ru', status='sleeping', started='17:37:29') did not respond to SIGTERM. Trying SIGKILL
[2025-07-19T17:39:15.450+0000] {process_utils.py:87} INFO - Sending the signal 9 to group 171
[2025-07-19T17:39:15.457+0000] {process_utils.py:80} INFO - Process psutil.Process(pid=171, name='airflow task ru', status='terminated', exitcode=<Negsignal.SIGKILL: -9>, started='17:37:29') (171) terminated with exit code -9
[2025-07-19T17:39:15.458+0000] {standard_task_runner.py:190} ERROR - ('Job 6 was killed before it finished (likely due to running out of memory)', 'For more information, see https://***.apache.org/docs/apache-***/stable/troubleshooting.html#LocalTaskJob-killed')
[2025-07-19T18:00:37.250+0000] {local_task_job_runner.py:123} INFO - ::group::Pre task execution logs
[2025-07-19T18:00:37.274+0000] {taskinstance.py:2603} INFO - Dependencies all met for dep_context=non-requeueable deps ti=<TaskInstance: banking_data_quality.generate_data scheduled__2025-07-18T17:00:00+00:00 [queued]>
[2025-07-19T18:00:37.288+0000] {taskinstance.py:2603} INFO - Dependencies all met for dep_context=requeueable deps ti=<TaskInstance: banking_data_quality.generate_data scheduled__2025-07-18T17:00:00+00:00 [queued]>
[2025-07-19T18:00:37.289+0000] {taskinstance.py:2856} INFO - Starting attempt 2 of 3
[2025-07-19T18:00:37.313+0000] {taskinstance.py:2879} INFO - Executing <Task(PythonOperator): generate_data> on 2025-07-18 17:00:00+00:00
[2025-07-19T18:00:37.327+0000] {warnings.py:112} WARNING - /home/***/.local/lib/python3.12/site-packages/***/task/task_runner/standard_task_runner.py:70: DeprecationWarning: This process (pid=86) is multi-threaded, use of fork() may lead to deadlocks in the child.
  pid = os.fork()

[2025-07-19T18:00:37.328+0000] {standard_task_runner.py:72} INFO - Started process 88 to run task
[2025-07-19T18:00:37.330+0000] {standard_task_runner.py:104} INFO - Running: ['***', 'tasks', 'run', 'banking_data_quality', 'generate_data', 'scheduled__2025-07-18T17:00:00+00:00', '--job-id', '5', '--raw', '--subdir', 'DAGS_FOLDER/banking_dq_dag.py', '--cfg-path', '/tmp/tmpcopdogf0']
[2025-07-19T18:00:37.333+0000] {standard_task_runner.py:105} INFO - Job 5: Subtask generate_data
[2025-07-19T18:00:37.399+0000] {task_command.py:467} INFO - Running <TaskInstance: banking_data_quality.generate_data scheduled__2025-07-18T17:00:00+00:00 [running]> on host 2e145ce6e7b6
[2025-07-19T18:00:37.506+0000] {taskinstance.py:3122} INFO - Exporting env vars: AIRFLOW_CTX_DAG_OWNER='***' AIRFLOW_CTX_DAG_ID='banking_data_quality' AIRFLOW_CTX_TASK_ID='generate_data' AIRFLOW_CTX_EXECUTION_DATE='2025-07-18T17:00:00+00:00' AIRFLOW_CTX_TRY_NUMBER='2' AIRFLOW_CTX_DAG_RUN_ID='scheduled__2025-07-18T17:00:00+00:00'
[2025-07-19T18:00:37.507+0000] {taskinstance.py:731} INFO - ::endgroup::
[2025-07-19T18:00:37.526+0000] {logging_mixin.py:190} INFO - --------connect success---------
[2025-07-19T18:00:37.597+0000] {logging_mixin.py:190} INFO - Data generation failed: 1146 (42S02): Table 'test.Customer' doesn't exist
[2025-07-19T18:00:37.597+0000] {taskinstance.py:3301} ERROR - Task failed with exception
Traceback (most recent call last):
  File "/home/airflow/.local/lib/python3.12/site-packages/mysql/connector/connection_cext.py", line 705, in cmd_query
    self._cmysql.query(
_mysql_connector.MySQLInterfaceError: Table 'test.Customer' doesn't exist

The above exception was the direct cause of the following exception:

Traceback (most recent call last):
  File "/home/airflow/.local/lib/python3.12/site-packages/airflow/models/taskinstance.py", line 767, in _execute_task
    result = _execute_callable(context=context, **execute_callable_kwargs)
             ^^^^^^^^^^^^^^^^^^^^^^^^^^^^^^^^^^^^^^^^^^^^^^^^^^^^^^^^^^^^^
  File "/home/airflow/.local/lib/python3.12/site-packages/airflow/models/taskinstance.py", line 733, in _execute_callable
    return ExecutionCallableRunner(
           ^^^^^^^^^^^^^^^^^^^^^^^^
  File "/home/airflow/.local/lib/python3.12/site-packages/airflow/utils/operator_helpers.py", line 252, in run
    return self.func(*args, **kwargs)
           ^^^^^^^^^^^^^^^^^^^^^^^^^^
  File "/home/airflow/.local/lib/python3.12/site-packages/airflow/models/baseoperator.py", line 406, in wrapper
    return func(self, *args, **kwargs)
           ^^^^^^^^^^^^^^^^^^^^^^^^^^^
  File "/home/airflow/.local/lib/python3.12/site-packages/airflow/operators/python.py", line 238, in execute
    return_value = self.execute_callable()
                   ^^^^^^^^^^^^^^^^^^^^^^^
  File "/home/airflow/.local/lib/python3.12/site-packages/airflow/operators/python.py", line 256, in execute_callable
    return runner.run(*self.op_args, **self.op_kwargs)
           ^^^^^^^^^^^^^^^^^^^^^^^^^^^^^^^^^^^^^^^^^^^
  File "/home/airflow/.local/lib/python3.12/site-packages/airflow/utils/operator_helpers.py", line 252, in run
    return self.func(*args, **kwargs)
           ^^^^^^^^^^^^^^^^^^^^^^^^^^
  File "/opt/airflow/dags/banking_dq_dag.py", line 32, in run_generate_data
    generate_data()
  File "/opt/airflow/include/generate_data.py", line 60, in generate_data
    cur.execute("""
  File "/home/airflow/.local/lib/python3.12/site-packages/mysql/connector/cursor_cext.py", line 357, in execute
    result = self._connection.cmd_query(
             ^^^^^^^^^^^^^^^^^^^^^^^^^^^
  File "/home/airflow/.local/lib/python3.12/site-packages/mysql/connector/opentelemetry/context_propagation.py", line 106, in wrapper
    result = method(cnx, *args, **kwargs)
             ^^^^^^^^^^^^^^^^^^^^^^^^^^^^
  File "/home/airflow/.local/lib/python3.12/site-packages/mysql/connector/connection_cext.py", line 713, in cmd_query
    raise get_mysql_exception(
mysql.connector.errors.ProgrammingError: 1146 (42S02): Table 'test.Customer' doesn't exist
[2025-07-19T18:00:37.621+0000] {taskinstance.py:1225} INFO - Marking task as UP_FOR_RETRY. dag_id=banking_data_quality, task_id=generate_data, run_id=scheduled__2025-07-18T17:00:00+00:00, execution_date=20250718T170000, start_date=20250719T180037, end_date=20250719T180037
[2025-07-19T18:00:37.642+0000] {taskinstance.py:340} INFO - ::group::Post task execution logs
[2025-07-19T18:00:37.642+0000] {standard_task_runner.py:124} ERROR - Failed to execute job 5 for task generate_data (1146 (42S02): Table 'test.Customer' doesn't exist; 88)
Traceback (most recent call last):
  File "/home/airflow/.local/lib/python3.12/site-packages/mysql/connector/connection_cext.py", line 705, in cmd_query
    self._cmysql.query(
_mysql_connector.MySQLInterfaceError: Table 'test.Customer' doesn't exist

The above exception was the direct cause of the following exception:

Traceback (most recent call last):
  File "/home/airflow/.local/lib/python3.12/site-packages/airflow/task/task_runner/standard_task_runner.py", line 117, in _start_by_fork
    ret = args.func(args, dag=self.dag)
          ^^^^^^^^^^^^^^^^^^^^^^^^^^^^^
  File "/home/airflow/.local/lib/python3.12/site-packages/airflow/cli/cli_config.py", line 49, in command
    return func(*args, **kwargs)
           ^^^^^^^^^^^^^^^^^^^^^
  File "/home/airflow/.local/lib/python3.12/site-packages/airflow/utils/cli.py", line 115, in wrapper
    return f(*args, **kwargs)
           ^^^^^^^^^^^^^^^^^^
  File "/home/airflow/.local/lib/python3.12/site-packages/airflow/cli/commands/task_command.py", line 483, in task_run
    task_return_code = _run_task_by_selected_method(args, _dag, ti)
                       ^^^^^^^^^^^^^^^^^^^^^^^^^^^^^^^^^^^^^^^^^^^^
  File "/home/airflow/.local/lib/python3.12/site-packages/airflow/cli/commands/task_command.py", line 256, in _run_task_by_selected_method
    return _run_raw_task(args, ti)
           ^^^^^^^^^^^^^^^^^^^^^^^
  File "/home/airflow/.local/lib/python3.12/site-packages/airflow/cli/commands/task_command.py", line 341, in _run_raw_task
    return ti._run_raw_task(
           ^^^^^^^^^^^^^^^^^
  File "/home/airflow/.local/lib/python3.12/site-packages/airflow/utils/session.py", line 97, in wrapper
    return func(*args, session=session, **kwargs)
           ^^^^^^^^^^^^^^^^^^^^^^^^^^^^^^^^^^^^^^
  File "/home/airflow/.local/lib/python3.12/site-packages/airflow/models/taskinstance.py", line 2995, in _run_raw_task
    return _run_raw_task(
           ^^^^^^^^^^^^^^
  File "/home/airflow/.local/lib/python3.12/site-packages/airflow/models/taskinstance.py", line 273, in _run_raw_task
    TaskInstance._execute_task_with_callbacks(
  File "/home/airflow/.local/lib/python3.12/site-packages/airflow/models/taskinstance.py", line 3149, in _execute_task_with_callbacks
    result = self._execute_task(context, task_orig)
             ^^^^^^^^^^^^^^^^^^^^^^^^^^^^^^^^^^^^^^
  File "/home/airflow/.local/lib/python3.12/site-packages/airflow/models/taskinstance.py", line 3173, in _execute_task
    return _execute_task(self, context, task_orig)
           ^^^^^^^^^^^^^^^^^^^^^^^^^^^^^^^^^^^^^^^
  File "/home/airflow/.local/lib/python3.12/site-packages/airflow/models/taskinstance.py", line 767, in _execute_task
    result = _execute_callable(context=context, **execute_callable_kwargs)
             ^^^^^^^^^^^^^^^^^^^^^^^^^^^^^^^^^^^^^^^^^^^^^^^^^^^^^^^^^^^^^
  File "/home/airflow/.local/lib/python3.12/site-packages/airflow/models/taskinstance.py", line 733, in _execute_callable
    return ExecutionCallableRunner(
           ^^^^^^^^^^^^^^^^^^^^^^^^
  File "/home/airflow/.local/lib/python3.12/site-packages/airflow/utils/operator_helpers.py", line 252, in run
    return self.func(*args, **kwargs)
           ^^^^^^^^^^^^^^^^^^^^^^^^^^
  File "/home/airflow/.local/lib/python3.12/site-packages/airflow/models/baseoperator.py", line 406, in wrapper
    return func(self, *args, **kwargs)
           ^^^^^^^^^^^^^^^^^^^^^^^^^^^
  File "/home/airflow/.local/lib/python3.12/site-packages/airflow/operators/python.py", line 238, in execute
    return_value = self.execute_callable()
                   ^^^^^^^^^^^^^^^^^^^^^^^
  File "/home/airflow/.local/lib/python3.12/site-packages/airflow/operators/python.py", line 256, in execute_callable
    return runner.run(*self.op_args, **self.op_kwargs)
           ^^^^^^^^^^^^^^^^^^^^^^^^^^^^^^^^^^^^^^^^^^^
  File "/home/airflow/.local/lib/python3.12/site-packages/airflow/utils/operator_helpers.py", line 252, in run
    return self.func(*args, **kwargs)
           ^^^^^^^^^^^^^^^^^^^^^^^^^^
  File "/opt/airflow/dags/banking_dq_dag.py", line 32, in run_generate_data
    generate_data()
  File "/opt/airflow/include/generate_data.py", line 60, in generate_data
    cur.execute("""
  File "/home/airflow/.local/lib/python3.12/site-packages/mysql/connector/cursor_cext.py", line 357, in execute
    result = self._connection.cmd_query(
             ^^^^^^^^^^^^^^^^^^^^^^^^^^^
  File "/home/airflow/.local/lib/python3.12/site-packages/mysql/connector/opentelemetry/context_propagation.py", line 106, in wrapper
    result = method(cnx, *args, **kwargs)
             ^^^^^^^^^^^^^^^^^^^^^^^^^^^^
  File "/home/airflow/.local/lib/python3.12/site-packages/mysql/connector/connection_cext.py", line 713, in cmd_query
    raise get_mysql_exception(
mysql.connector.errors.ProgrammingError: 1146 (42S02): Table 'test.Customer' doesn't exist
[2025-07-19T18:00:37.663+0000] {local_task_job_runner.py:261} INFO - Task exited with return code 1
[2025-07-19T18:00:37.690+0000] {taskinstance.py:3891} INFO - 0 downstream tasks scheduled from follow-on schedule check
[2025-07-19T18:00:37.692+0000] {local_task_job_runner.py:240} INFO - ::endgroup::
[2025-07-19T18:15:21.990+0000] {local_task_job_runner.py:123} INFO - ::group::Pre task execution logs
[2025-07-19T18:15:22.009+0000] {taskinstance.py:2603} INFO - Dependencies all met for dep_context=non-requeueable deps ti=<TaskInstance: banking_data_quality.generate_data scheduled__2025-07-18T17:00:00+00:00 [queued]>
[2025-07-19T18:15:22.019+0000] {taskinstance.py:2603} INFO - Dependencies all met for dep_context=requeueable deps ti=<TaskInstance: banking_data_quality.generate_data scheduled__2025-07-18T17:00:00+00:00 [queued]>
[2025-07-19T18:15:22.020+0000] {taskinstance.py:2856} INFO - Starting attempt 2 of 3
[2025-07-19T18:15:22.036+0000] {taskinstance.py:2879} INFO - Executing <Task(PythonOperator): generate_data> on 2025-07-18 17:00:00+00:00
[2025-07-19T18:15:22.045+0000] {warnings.py:112} WARNING - /home/***/.local/lib/python3.12/site-packages/***/task/task_runner/standard_task_runner.py:70: DeprecationWarning: This process (pid=86) is multi-threaded, use of fork() may lead to deadlocks in the child.
  pid = os.fork()

[2025-07-19T18:15:22.047+0000] {standard_task_runner.py:72} INFO - Started process 88 to run task
[2025-07-19T18:15:22.047+0000] {standard_task_runner.py:104} INFO - Running: ['***', 'tasks', 'run', 'banking_data_quality', 'generate_data', 'scheduled__2025-07-18T17:00:00+00:00', '--job-id', '5', '--raw', '--subdir', 'DAGS_FOLDER/banking_dq_dag.py', '--cfg-path', '/tmp/tmp5evdpzl5']
[2025-07-19T18:15:22.049+0000] {standard_task_runner.py:105} INFO - Job 5: Subtask generate_data
[2025-07-19T18:15:22.095+0000] {task_command.py:467} INFO - Running <TaskInstance: banking_data_quality.generate_data scheduled__2025-07-18T17:00:00+00:00 [running]> on host 357ca0968dee
[2025-07-19T18:15:22.184+0000] {taskinstance.py:3122} INFO - Exporting env vars: AIRFLOW_CTX_DAG_OWNER='***' AIRFLOW_CTX_DAG_ID='banking_data_quality' AIRFLOW_CTX_TASK_ID='generate_data' AIRFLOW_CTX_EXECUTION_DATE='2025-07-18T17:00:00+00:00' AIRFLOW_CTX_TRY_NUMBER='2' AIRFLOW_CTX_DAG_RUN_ID='scheduled__2025-07-18T17:00:00+00:00'
[2025-07-19T18:15:22.186+0000] {taskinstance.py:731} INFO - ::endgroup::
[2025-07-19T18:15:22.201+0000] {logging_mixin.py:190} INFO - --------connect success---------
[2025-07-19T18:15:22.286+0000] {logging_mixin.py:190} INFO - customers = [21, 22, 23, 24, 25, 26, 27, 28, 29, 30]
[2025-07-19T18:15:22.295+0000] {logging_mixin.py:190} INFO - accounts = [40, 41, 42, 43, 44, 45, 46, 47, 48, 49, 50, 51, 52, 53, 54, 55]
[2025-07-19T18:15:22.308+0000] {logging_mixin.py:190} INFO - cards = [57, 58, 59, 60, 61, 62, 63, 64, 65, 66, 67, 68, 69, 70, 71, 72, 73, 74, 75, 76, 77]
[2025-07-19T18:15:22.319+0000] {logging_mixin.py:190} INFO - merchants = [21, 22, 23, 24, 25, 26, 27, 28, 29, 30]
[2025-07-19T18:15:22.348+0000] {logging_mixin.py:190} INFO - devices = [38, 39, 40, 41, 42, 43, 44, 45, 46, 47, 48, 49, 50, 51, 52, 53, 54, 55, 56, 57]
[2025-07-19T18:15:22.363+0000] {logging_mixin.py:190} INFO - auth_logs = [41, 42, 43, 44, 45, 46, 47, 48, 49, 50, 51, 52, 53, 54, 55, 56, 57, 58, 59, 60]
[2025-07-19T18:15:22.417+0000] {logging_mixin.py:190} INFO - Sample data generated successfully.
[2025-07-19T18:15:22.417+0000] {logging_mixin.py:190} INFO - Data generation completed successfully.
[2025-07-19T18:15:22.418+0000] {python.py:240} INFO - Done. Returned value was: None
[2025-07-19T18:15:22.428+0000] {taskinstance.py:340} INFO - ::group::Post task execution logs
[2025-07-19T18:15:22.428+0000] {taskinstance.py:352} INFO - Marking task as SUCCESS. dag_id=banking_data_quality, task_id=generate_data, run_id=scheduled__2025-07-18T17:00:00+00:00, execution_date=20250718T170000, start_date=20250719T181522, end_date=20250719T181522
[2025-07-19T18:15:22.461+0000] {local_task_job_runner.py:261} INFO - Task exited with return code 0
[2025-07-19T18:15:22.492+0000] {taskinstance.py:3891} INFO - 1 downstream tasks scheduled from follow-on schedule check
[2025-07-19T18:15:22.494+0000] {local_task_job_runner.py:240} INFO - ::endgroup::
