[2025-07-19T17:38:39.255+0000] {local_task_job_runner.py:123} INFO - ::group::Pre task execution logs
[2025-07-19T17:38:39.279+0000] {taskinstance.py:2603} INFO - Dependencies all met for dep_context=non-requeueable deps ti=<TaskInstance: banking_data_quality.generate_data scheduled__2025-07-18T17:00:00+00:00 [queued]>
[2025-07-19T17:38:39.290+0000] {taskinstance.py:2603} INFO - Dependencies all met for dep_context=requeueable deps ti=<TaskInstance: banking_data_quality.generate_data scheduled__2025-07-18T17:00:00+00:00 [queued]>
[2025-07-19T17:38:39.290+0000] {taskinstance.py:2856} INFO - Starting attempt 3 of 4
[2025-07-19T17:38:39.305+0000] {taskinstance.py:2879} INFO - Executing <Task(PythonOperator): generate_data> on 2025-07-18 17:00:00+00:00
[2025-07-19T17:38:39.316+0000] {warnings.py:112} WARNING - /home/***/.local/lib/python3.12/site-packages/***/task/task_runner/standard_task_runner.py:70: DeprecationWarning: This process (pid=187) is multi-threaded, use of fork() may lead to deadlocks in the child.
  pid = os.fork()

[2025-07-19T17:38:39.317+0000] {standard_task_runner.py:72} INFO - Started process 189 to run task
[2025-07-19T17:38:39.318+0000] {standard_task_runner.py:104} INFO - Running: ['***', 'tasks', 'run', 'banking_data_quality', 'generate_data', 'scheduled__2025-07-18T17:00:00+00:00', '--job-id', '7', '--raw', '--subdir', 'DAGS_FOLDER/banking_dq_dag.py', '--cfg-path', '/tmp/tmpbaxp8n23']
[2025-07-19T17:38:39.320+0000] {standard_task_runner.py:105} INFO - Job 7: Subtask generate_data
[2025-07-19T17:38:39.382+0000] {task_command.py:467} INFO - Running <TaskInstance: banking_data_quality.generate_data scheduled__2025-07-18T17:00:00+00:00 [running]> on host 894e965ab49e
[2025-07-19T17:38:39.497+0000] {taskinstance.py:3122} INFO - Exporting env vars: AIRFLOW_CTX_DAG_OWNER='***' AIRFLOW_CTX_DAG_ID='banking_data_quality' AIRFLOW_CTX_TASK_ID='generate_data' AIRFLOW_CTX_EXECUTION_DATE='2025-07-18T17:00:00+00:00' AIRFLOW_CTX_TRY_NUMBER='3' AIRFLOW_CTX_DAG_RUN_ID='scheduled__2025-07-18T17:00:00+00:00'
[2025-07-19T17:38:39.499+0000] {taskinstance.py:731} INFO - ::endgroup::
[2025-07-19T17:38:39.516+0000] {logging_mixin.py:190} INFO - --------connect success---------
[2025-07-19T17:40:15.218+0000] {local_task_job_runner.py:341} WARNING - State of this instance has been externally set to restarting. Terminating instance.
[2025-07-19T17:40:15.219+0000] {local_task_job_runner.py:240} INFO - ::endgroup::
[2025-07-19T17:40:15.220+0000] {process_utils.py:132} INFO - Sending 15 to group 189. PIDs of all processes in the group: [189]
[2025-07-19T17:40:15.221+0000] {process_utils.py:87} INFO - Sending the signal 15 to group 189
[2025-07-19T17:40:52.245+0000] {taskinstance.py:3083} ERROR - Received SIGTERM. Terminating subprocesses.
[2025-07-19T17:40:52.253+0000] {taskinstance.py:3301} ERROR - Task failed with exception
Traceback (most recent call last):
  File "/home/airflow/.local/lib/python3.12/site-packages/mysql/connector/connection_cext.py", line 334, in _open_connection
    self._cmysql.connect(**cnx_kwargs)
_mysql_connector.MySQLInterfaceError: Can't connect to MySQL server on '172.17.0.2:3306' (110)

During handling of the above exception, another exception occurred:

Traceback (most recent call last):
  File "/home/airflow/.local/lib/python3.12/site-packages/airflow/models/taskinstance.py", line 767, in _execute_task
    result = _execute_callable(context=context, **execute_callable_kwargs)
             ^^^^^^^^^^^^^^^^^^^^^^^^^^^^^^^^^^^^^^^^^^^^^^^^^^^^^^^^^^^^^
  File "/home/airflow/.local/lib/python3.12/site-packages/airflow/models/taskinstance.py", line 733, in _execute_callable
    return ExecutionCallableRunner(
           ^^^^^^^^^^^^^^^^^^^^^^^^
  File "/home/airflow/.local/lib/python3.12/site-packages/airflow/utils/operator_helpers.py", line 252, in run
    return self.func(*args, **kwargs)
           ^^^^^^^^^^^^^^^^^^^^^^^^^^
  File "/home/airflow/.local/lib/python3.12/site-packages/airflow/models/baseoperator.py", line 406, in wrapper
    return func(self, *args, **kwargs)
           ^^^^^^^^^^^^^^^^^^^^^^^^^^^
  File "/home/airflow/.local/lib/python3.12/site-packages/airflow/operators/python.py", line 238, in execute
    return_value = self.execute_callable()
                   ^^^^^^^^^^^^^^^^^^^^^^^
  File "/home/airflow/.local/lib/python3.12/site-packages/airflow/operators/python.py", line 256, in execute_callable
    return runner.run(*self.op_args, **self.op_kwargs)
           ^^^^^^^^^^^^^^^^^^^^^^^^^^^^^^^^^^^^^^^^^^^
  File "/home/airflow/.local/lib/python3.12/site-packages/airflow/utils/operator_helpers.py", line 252, in run
    return self.func(*args, **kwargs)
           ^^^^^^^^^^^^^^^^^^^^^^^^^^
  File "/opt/airflow/dags/banking_dq_dag.py", line 32, in run_generate_data
    generate_data()
  File "/opt/airflow/include/generate_data.py", line 40, in generate_data
    conn = connect_db()
           ^^^^^^^^^^^^
  File "/opt/airflow/include/generate_data.py", line 23, in connect_db
    return mysql.connector.connect(**DB_PARAMS)
           ^^^^^^^^^^^^^^^^^^^^^^^^^^^^^^^^^^^^
  File "/home/airflow/.local/lib/python3.12/site-packages/mysql/connector/pooling.py", line 322, in connect
    return CMySQLConnection(*args, **kwargs)
           ^^^^^^^^^^^^^^^^^^^^^^^^^^^^^^^^^
  File "/home/airflow/.local/lib/python3.12/site-packages/mysql/connector/connection_cext.py", line 151, in __init__
    self.connect(**kwargs)
  File "/home/airflow/.local/lib/python3.12/site-packages/mysql/connector/abstracts.py", line 1399, in connect
    self._open_connection()
  File "/home/airflow/.local/lib/python3.12/site-packages/mysql/connector/connection_cext.py", line 339, in _open_connection
    raise get_mysql_exception(
          ^^^^^^^^^^^^^^^^^^^^
  File "/home/airflow/.local/lib/python3.12/site-packages/mysql/connector/errors.py", line 222, in get_mysql_exception
    def get_mysql_exception(
    
  File "/home/airflow/.local/lib/python3.12/site-packages/airflow/models/taskinstance.py", line 3085, in signal_handler
    raise AirflowTaskTerminated("Task received SIGTERM signal")
airflow.exceptions.AirflowTaskTerminated: Task received SIGTERM signal
[2025-07-19T17:40:52.269+0000] {taskinstance.py:1225} INFO - Marking task as UP_FOR_RETRY. dag_id=banking_data_quality, task_id=generate_data, run_id=scheduled__2025-07-18T17:00:00+00:00, execution_date=20250718T170000, start_date=20250719T174019, end_date=20250719T174052
[2025-07-19T17:40:52.282+0000] {taskinstance.py:340} INFO - ::group::Post task execution logs
[2025-07-19T17:40:52.320+0000] {process_utils.py:80} INFO - Process psutil.Process(pid=189, status='terminated', exitcode=2, started='17:38:39') (189) terminated with exit code 2
[2025-07-19T18:02:12.224+0000] {local_task_job_runner.py:123} INFO - ::group::Pre task execution logs
[2025-07-19T18:02:12.246+0000] {taskinstance.py:2603} INFO - Dependencies all met for dep_context=non-requeueable deps ti=<TaskInstance: banking_data_quality.generate_data scheduled__2025-07-18T17:00:00+00:00 [None]>
[2025-07-19T18:02:12.255+0000] {taskinstance.py:2603} INFO - Dependencies all met for dep_context=requeueable deps ti=<TaskInstance: banking_data_quality.generate_data scheduled__2025-07-18T17:00:00+00:00 [None]>
[2025-07-19T18:02:12.255+0000] {taskinstance.py:2856} INFO - Starting attempt 3 of 5
[2025-07-19T18:02:12.271+0000] {taskinstance.py:2879} INFO - Executing <Task(PythonOperator): generate_data> on 2025-07-18 17:00:00+00:00
[2025-07-19T18:02:12.281+0000] {warnings.py:112} WARNING - /home/***/.local/lib/python3.12/site-packages/***/task/task_runner/standard_task_runner.py:70: DeprecationWarning: This process (pid=111) is multi-threaded, use of fork() may lead to deadlocks in the child.
  pid = os.fork()

[2025-07-19T18:02:12.282+0000] {standard_task_runner.py:72} INFO - Started process 113 to run task
[2025-07-19T18:02:12.283+0000] {standard_task_runner.py:104} INFO - Running: ['***', 'tasks', 'run', 'banking_data_quality', 'generate_data', 'scheduled__2025-07-18T17:00:00+00:00', '--job-id', '6', '--raw', '--subdir', 'DAGS_FOLDER/banking_dq_dag.py', '--cfg-path', '/tmp/tmpbz773uey']
[2025-07-19T18:02:12.286+0000] {standard_task_runner.py:105} INFO - Job 6: Subtask generate_data
[2025-07-19T18:02:12.333+0000] {task_command.py:467} INFO - Running <TaskInstance: banking_data_quality.generate_data scheduled__2025-07-18T17:00:00+00:00 [running]> on host 2e145ce6e7b6
[2025-07-19T18:02:12.424+0000] {taskinstance.py:3122} INFO - Exporting env vars: AIRFLOW_CTX_DAG_OWNER='***' AIRFLOW_CTX_DAG_ID='banking_data_quality' AIRFLOW_CTX_TASK_ID='generate_data' AIRFLOW_CTX_EXECUTION_DATE='2025-07-18T17:00:00+00:00' AIRFLOW_CTX_TRY_NUMBER='3' AIRFLOW_CTX_DAG_RUN_ID='scheduled__2025-07-18T17:00:00+00:00'
[2025-07-19T18:02:12.425+0000] {taskinstance.py:731} INFO - ::endgroup::
[2025-07-19T18:02:12.440+0000] {logging_mixin.py:190} INFO - --------connect success---------
[2025-07-19T18:02:12.506+0000] {logging_mixin.py:190} INFO - customers = [1, 2, 3, 4, 5, 6, 7, 8, 9, 10]
[2025-07-19T18:02:12.519+0000] {logging_mixin.py:190} INFO - accounts = [1, 2, 3, 4, 5, 6, 7, 8, 9, 10, 11, 12, 13, 14, 15, 16, 17, 18, 19]
[2025-07-19T18:02:12.537+0000] {logging_mixin.py:190} INFO - cards = [1, 2, 3, 4, 5, 6, 7, 8, 9, 10, 11, 12, 13, 14, 15, 16, 17, 18, 19, 20, 21, 22, 23, 24, 25, 26, 27, 28, 29, 30, 31, 32]
[2025-07-19T18:02:12.552+0000] {logging_mixin.py:190} INFO - merchants = [1, 2, 3, 4, 5, 6, 7, 8, 9, 10]
[2025-07-19T18:02:12.579+0000] {logging_mixin.py:190} INFO - devices = [1, 2, 3, 4, 5, 6, 7, 8, 9, 10, 11, 12, 13, 14, 15, 16, 17]
[2025-07-19T18:02:12.589+0000] {logging_mixin.py:190} INFO - auth_logs = [1, 2, 3, 4, 5, 6, 7, 8, 9, 10, 11, 12, 13, 14, 15, 16, 17, 18, 19, 20]
[2025-07-19T18:02:12.629+0000] {logging_mixin.py:190} INFO - Sample data generated successfully.
[2025-07-19T18:02:12.630+0000] {logging_mixin.py:190} INFO - Data generation completed successfully.
[2025-07-19T18:02:12.630+0000] {python.py:240} INFO - Done. Returned value was: None
[2025-07-19T18:02:12.640+0000] {taskinstance.py:340} INFO - ::group::Post task execution logs
[2025-07-19T18:02:12.641+0000] {taskinstance.py:352} INFO - Marking task as SUCCESS. dag_id=banking_data_quality, task_id=generate_data, run_id=scheduled__2025-07-18T17:00:00+00:00, execution_date=20250718T170000, start_date=20250719T180212, end_date=20250719T180212
[2025-07-19T18:02:12.697+0000] {local_task_job_runner.py:261} INFO - Task exited with return code 0
[2025-07-19T18:02:12.727+0000] {taskinstance.py:3891} INFO - 1 downstream tasks scheduled from follow-on schedule check
[2025-07-19T18:02:12.729+0000] {local_task_job_runner.py:240} INFO - ::endgroup::
