[2025-07-19T18:03:59.024+0000] {local_task_job_runner.py:123} INFO - ::group::Pre task execution logs
[2025-07-19T18:03:59.044+0000] {taskinstance.py:2603} INFO - Dependencies all met for dep_context=non-requeueable deps ti=<TaskInstance: banking_data_quality.run_monitoring_audit scheduled__2025-07-18T17:00:00+00:00 [queued]>
[2025-07-19T18:03:59.054+0000] {taskinstance.py:2603} INFO - Dependencies all met for dep_context=requeueable deps ti=<TaskInstance: banking_data_quality.run_monitoring_audit scheduled__2025-07-18T17:00:00+00:00 [queued]>
[2025-07-19T18:03:59.054+0000] {taskinstance.py:2856} INFO - Starting attempt 1 of 2
[2025-07-19T18:03:59.071+0000] {taskinstance.py:2879} INFO - Executing <Task(PythonOperator): run_monitoring_audit> on 2025-07-18 17:00:00+00:00
[2025-07-19T18:03:59.079+0000] {warnings.py:112} WARNING - /home/***/.local/lib/python3.12/site-packages/***/task/task_runner/standard_task_runner.py:70: DeprecationWarning: This process (pid=148) is multi-threaded, use of fork() may lead to deadlocks in the child.
  pid = os.fork()

[2025-07-19T18:03:59.080+0000] {standard_task_runner.py:72} INFO - Started process 150 to run task
[2025-07-19T18:03:59.081+0000] {standard_task_runner.py:104} INFO - Running: ['***', 'tasks', 'run', 'banking_data_quality', 'run_monitoring_audit', 'scheduled__2025-07-18T17:00:00+00:00', '--job-id', '10', '--raw', '--subdir', 'DAGS_FOLDER/banking_dq_dag.py', '--cfg-path', '/tmp/tmprxpwlz0a']
[2025-07-19T18:03:59.083+0000] {standard_task_runner.py:105} INFO - Job 10: Subtask run_monitoring_audit
[2025-07-19T18:03:59.129+0000] {task_command.py:467} INFO - Running <TaskInstance: banking_data_quality.run_monitoring_audit scheduled__2025-07-18T17:00:00+00:00 [running]> on host 2e145ce6e7b6
[2025-07-19T18:03:59.209+0000] {taskinstance.py:3122} INFO - Exporting env vars: AIRFLOW_CTX_DAG_OWNER='***' AIRFLOW_CTX_DAG_ID='banking_data_quality' AIRFLOW_CTX_TASK_ID='run_monitoring_audit' AIRFLOW_CTX_EXECUTION_DATE='2025-07-18T17:00:00+00:00' AIRFLOW_CTX_TRY_NUMBER='1' AIRFLOW_CTX_DAG_RUN_ID='scheduled__2025-07-18T17:00:00+00:00'
[2025-07-19T18:03:59.210+0000] {taskinstance.py:731} INFO - ::endgroup::
[2025-07-19T18:03:59.387+0000] {logging_mixin.py:190} INFO - 
Monitoring and Audit Summary:
[2025-07-19T18:03:59.412+0000] {logging_mixin.py:190} INFO -                           Check  ...                                            Details
0   High-Value Transaction Auth  ...       61 transactions >10M VND without strong auth
1       Unverified Device Usage  ...            37 transactions from unverified devices
2  Daily Transaction Limit Auth  ...  3 customers with >20M VND/day without strong auth

[3 rows x 3 columns]
[2025-07-19T18:03:59.415+0000] {logging_mixin.py:190} INFO - 
Failed Checks:
[2025-07-19T18:03:59.423+0000] {logging_mixin.py:190} INFO -                           Check  ...                                            Details
0   High-Value Transaction Auth  ...       61 transactions >10M VND without strong auth
1       Unverified Device Usage  ...            37 transactions from unverified devices
2  Daily Transaction Limit Auth  ...  3 customers with >20M VND/day without strong auth

[3 rows x 3 columns]
[2025-07-19T18:03:59.426+0000] {logging_mixin.py:190} INFO - Monitoring checks failed: {'Check': {0: 'High-Value Transaction Auth', 1: 'Unverified Device Usage', 2: 'Daily Transaction Limit Auth'}, 'Status': {0: 'FAIL', 1: 'FAIL', 2: 'FAIL'}, 'Details': {0: '61 transactions >10M VND without strong auth', 1: '37 transactions from unverified devices', 2: '3 customers with >20M VND/day without strong auth'}}
[2025-07-19T18:03:59.426+0000] {logging_mixin.py:190} INFO - Monitoring checks failed: Monitoring checks failed
[2025-07-19T18:03:59.426+0000] {taskinstance.py:3301} ERROR - Task failed with exception
Traceback (most recent call last):
  File "/home/airflow/.local/lib/python3.12/site-packages/airflow/models/taskinstance.py", line 767, in _execute_task
    result = _execute_callable(context=context, **execute_callable_kwargs)
             ^^^^^^^^^^^^^^^^^^^^^^^^^^^^^^^^^^^^^^^^^^^^^^^^^^^^^^^^^^^^^
  File "/home/airflow/.local/lib/python3.12/site-packages/airflow/models/taskinstance.py", line 733, in _execute_callable
    return ExecutionCallableRunner(
           ^^^^^^^^^^^^^^^^^^^^^^^^
  File "/home/airflow/.local/lib/python3.12/site-packages/airflow/utils/operator_helpers.py", line 252, in run
    return self.func(*args, **kwargs)
           ^^^^^^^^^^^^^^^^^^^^^^^^^^
  File "/home/airflow/.local/lib/python3.12/site-packages/airflow/models/baseoperator.py", line 406, in wrapper
    return func(self, *args, **kwargs)
           ^^^^^^^^^^^^^^^^^^^^^^^^^^^
  File "/home/airflow/.local/lib/python3.12/site-packages/airflow/operators/python.py", line 238, in execute
    return_value = self.execute_callable()
                   ^^^^^^^^^^^^^^^^^^^^^^^
  File "/home/airflow/.local/lib/python3.12/site-packages/airflow/operators/python.py", line 256, in execute_callable
    return runner.run(*self.op_args, **self.op_kwargs)
           ^^^^^^^^^^^^^^^^^^^^^^^^^^^^^^^^^^^^^^^^^^^
  File "/home/airflow/.local/lib/python3.12/site-packages/airflow/utils/operator_helpers.py", line 252, in run
    return self.func(*args, **kwargs)
           ^^^^^^^^^^^^^^^^^^^^^^^^^^
  File "/opt/airflow/dags/banking_dq_dag.py", line 56, in run_monitoring_audit_task
    raise Exception("Monitoring checks failed")
Exception: Monitoring checks failed
[2025-07-19T18:03:59.439+0000] {taskinstance.py:1225} INFO - Marking task as UP_FOR_RETRY. dag_id=banking_data_quality, task_id=run_monitoring_audit, run_id=scheduled__2025-07-18T17:00:00+00:00, execution_date=20250718T170000, start_date=20250719T180359, end_date=20250719T180359
[2025-07-19T18:03:59.455+0000] {taskinstance.py:340} INFO - ::group::Post task execution logs
[2025-07-19T18:03:59.456+0000] {standard_task_runner.py:124} ERROR - Failed to execute job 10 for task run_monitoring_audit (Monitoring checks failed; 150)
Traceback (most recent call last):
  File "/home/airflow/.local/lib/python3.12/site-packages/airflow/task/task_runner/standard_task_runner.py", line 117, in _start_by_fork
    ret = args.func(args, dag=self.dag)
          ^^^^^^^^^^^^^^^^^^^^^^^^^^^^^
  File "/home/airflow/.local/lib/python3.12/site-packages/airflow/cli/cli_config.py", line 49, in command
    return func(*args, **kwargs)
           ^^^^^^^^^^^^^^^^^^^^^
  File "/home/airflow/.local/lib/python3.12/site-packages/airflow/utils/cli.py", line 115, in wrapper
    return f(*args, **kwargs)
           ^^^^^^^^^^^^^^^^^^
  File "/home/airflow/.local/lib/python3.12/site-packages/airflow/cli/commands/task_command.py", line 483, in task_run
    task_return_code = _run_task_by_selected_method(args, _dag, ti)
                       ^^^^^^^^^^^^^^^^^^^^^^^^^^^^^^^^^^^^^^^^^^^^
  File "/home/airflow/.local/lib/python3.12/site-packages/airflow/cli/commands/task_command.py", line 256, in _run_task_by_selected_method
    return _run_raw_task(args, ti)
           ^^^^^^^^^^^^^^^^^^^^^^^
  File "/home/airflow/.local/lib/python3.12/site-packages/airflow/cli/commands/task_command.py", line 341, in _run_raw_task
    return ti._run_raw_task(
           ^^^^^^^^^^^^^^^^^
  File "/home/airflow/.local/lib/python3.12/site-packages/airflow/utils/session.py", line 97, in wrapper
    return func(*args, session=session, **kwargs)
           ^^^^^^^^^^^^^^^^^^^^^^^^^^^^^^^^^^^^^^
  File "/home/airflow/.local/lib/python3.12/site-packages/airflow/models/taskinstance.py", line 2995, in _run_raw_task
    return _run_raw_task(
           ^^^^^^^^^^^^^^
  File "/home/airflow/.local/lib/python3.12/site-packages/airflow/models/taskinstance.py", line 273, in _run_raw_task
    TaskInstance._execute_task_with_callbacks(
  File "/home/airflow/.local/lib/python3.12/site-packages/airflow/models/taskinstance.py", line 3149, in _execute_task_with_callbacks
    result = self._execute_task(context, task_orig)
             ^^^^^^^^^^^^^^^^^^^^^^^^^^^^^^^^^^^^^^
  File "/home/airflow/.local/lib/python3.12/site-packages/airflow/models/taskinstance.py", line 3173, in _execute_task
    return _execute_task(self, context, task_orig)
           ^^^^^^^^^^^^^^^^^^^^^^^^^^^^^^^^^^^^^^^
  File "/home/airflow/.local/lib/python3.12/site-packages/airflow/models/taskinstance.py", line 767, in _execute_task
    result = _execute_callable(context=context, **execute_callable_kwargs)
             ^^^^^^^^^^^^^^^^^^^^^^^^^^^^^^^^^^^^^^^^^^^^^^^^^^^^^^^^^^^^^
  File "/home/airflow/.local/lib/python3.12/site-packages/airflow/models/taskinstance.py", line 733, in _execute_callable
    return ExecutionCallableRunner(
           ^^^^^^^^^^^^^^^^^^^^^^^^
  File "/home/airflow/.local/lib/python3.12/site-packages/airflow/utils/operator_helpers.py", line 252, in run
    return self.func(*args, **kwargs)
           ^^^^^^^^^^^^^^^^^^^^^^^^^^
  File "/home/airflow/.local/lib/python3.12/site-packages/airflow/models/baseoperator.py", line 406, in wrapper
    return func(self, *args, **kwargs)
           ^^^^^^^^^^^^^^^^^^^^^^^^^^^
  File "/home/airflow/.local/lib/python3.12/site-packages/airflow/operators/python.py", line 238, in execute
    return_value = self.execute_callable()
                   ^^^^^^^^^^^^^^^^^^^^^^^
  File "/home/airflow/.local/lib/python3.12/site-packages/airflow/operators/python.py", line 256, in execute_callable
    return runner.run(*self.op_args, **self.op_kwargs)
           ^^^^^^^^^^^^^^^^^^^^^^^^^^^^^^^^^^^^^^^^^^^
  File "/home/airflow/.local/lib/python3.12/site-packages/airflow/utils/operator_helpers.py", line 252, in run
    return self.func(*args, **kwargs)
           ^^^^^^^^^^^^^^^^^^^^^^^^^^
  File "/opt/airflow/dags/banking_dq_dag.py", line 56, in run_monitoring_audit_task
    raise Exception("Monitoring checks failed")
Exception: Monitoring checks failed
[2025-07-19T18:03:59.495+0000] {local_task_job_runner.py:261} INFO - Task exited with return code 1
[2025-07-19T18:03:59.513+0000] {taskinstance.py:3891} INFO - 0 downstream tasks scheduled from follow-on schedule check
[2025-07-19T18:03:59.515+0000] {local_task_job_runner.py:240} INFO - ::endgroup::
[2025-07-19T18:15:27.062+0000] {local_task_job_runner.py:123} INFO - ::group::Pre task execution logs
[2025-07-19T18:15:27.078+0000] {taskinstance.py:2603} INFO - Dependencies all met for dep_context=non-requeueable deps ti=<TaskInstance: banking_data_quality.run_monitoring_audit scheduled__2025-07-18T17:00:00+00:00 [queued]>
[2025-07-19T18:15:27.087+0000] {taskinstance.py:2603} INFO - Dependencies all met for dep_context=requeueable deps ti=<TaskInstance: banking_data_quality.run_monitoring_audit scheduled__2025-07-18T17:00:00+00:00 [queued]>
[2025-07-19T18:15:27.087+0000] {taskinstance.py:2856} INFO - Starting attempt 1 of 2
[2025-07-19T18:15:27.100+0000] {taskinstance.py:2879} INFO - Executing <Task(PythonOperator): run_monitoring_audit> on 2025-07-18 17:00:00+00:00
[2025-07-19T18:15:27.108+0000] {warnings.py:112} WARNING - /home/***/.local/lib/python3.12/site-packages/***/task/task_runner/standard_task_runner.py:70: DeprecationWarning: This process (pid=94) is multi-threaded, use of fork() may lead to deadlocks in the child.
  pid = os.fork()

[2025-07-19T18:15:27.109+0000] {standard_task_runner.py:72} INFO - Started process 96 to run task
[2025-07-19T18:15:27.110+0000] {standard_task_runner.py:104} INFO - Running: ['***', 'tasks', 'run', 'banking_data_quality', 'run_monitoring_audit', 'scheduled__2025-07-18T17:00:00+00:00', '--job-id', '7', '--raw', '--subdir', 'DAGS_FOLDER/banking_dq_dag.py', '--cfg-path', '/tmp/tmpzvuxwoq8']
[2025-07-19T18:15:27.112+0000] {standard_task_runner.py:105} INFO - Job 7: Subtask run_monitoring_audit
[2025-07-19T18:15:27.154+0000] {task_command.py:467} INFO - Running <TaskInstance: banking_data_quality.run_monitoring_audit scheduled__2025-07-18T17:00:00+00:00 [running]> on host 357ca0968dee
[2025-07-19T18:15:27.237+0000] {taskinstance.py:3122} INFO - Exporting env vars: AIRFLOW_CTX_DAG_OWNER='***' AIRFLOW_CTX_DAG_ID='banking_data_quality' AIRFLOW_CTX_TASK_ID='run_monitoring_audit' AIRFLOW_CTX_EXECUTION_DATE='2025-07-18T17:00:00+00:00' AIRFLOW_CTX_TRY_NUMBER='1' AIRFLOW_CTX_DAG_RUN_ID='scheduled__2025-07-18T17:00:00+00:00'
[2025-07-19T18:15:27.238+0000] {taskinstance.py:731} INFO - ::endgroup::
[2025-07-19T18:15:27.383+0000] {logging_mixin.py:190} INFO - 
Monitoring and Audit Summary:
[2025-07-19T18:15:27.383+0000] {logging_mixin.py:190} INFO - checks = [{'Check': 'High-Value Transaction Auth', 'Status': 'FAIL', 'Details': '90 transactions >10M VND without strong auth'}, {'Check': 'Unverified Device Usage', 'Status': 'FAIL', 'Details': '60 transactions from unverified devices'}, {'Check': 'Daily Transaction Limit Auth', 'Status': 'FAIL', 'Details': '4 customers with >20M VND/day without strong auth'}]
[2025-07-19T18:15:27.384+0000] {logging_mixin.py:190} INFO - Monitoring checks passed.
[2025-07-19T18:15:27.384+0000] {logging_mixin.py:190} INFO - checks = None
[2025-07-19T18:15:27.384+0000] {python.py:240} INFO - Done. Returned value was: None
[2025-07-19T18:15:27.396+0000] {taskinstance.py:340} INFO - ::group::Post task execution logs
[2025-07-19T18:15:27.397+0000] {taskinstance.py:352} INFO - Marking task as SUCCESS. dag_id=banking_data_quality, task_id=run_monitoring_audit, run_id=scheduled__2025-07-18T17:00:00+00:00, execution_date=20250718T170000, start_date=20250719T181527, end_date=20250719T181527
[2025-07-19T18:15:27.444+0000] {local_task_job_runner.py:261} INFO - Task exited with return code 0
[2025-07-19T18:15:27.460+0000] {taskinstance.py:3891} INFO - 0 downstream tasks scheduled from follow-on schedule check
[2025-07-19T18:15:27.462+0000] {local_task_job_runner.py:240} INFO - ::endgroup::
